<?xml version="1.0" ?>
<robot name="basicBoomBot" xmlns:xacro="http://www.ros.org/wiki/xacro">

<xacro:include filename="$(find basicBoomBot_description)/urdf/materials.xacro" />
<xacro:include filename="$(find basicBoomBot_description)/urdf/basicBoomBot.trans" />
<xacro:include filename="$(find basicBoomBot_description)/urdf/basicBoomBot.gazebo" />
<link name="base_link">
  <inertial>
    <origin xyz="0.0029896973924744713 0.0 0.046973389333056365" rpy="0 0 0"/>
    <mass value="0.2880192546991266"/>
    <inertia ixx="0.00044" iyy="0.000629" izz="0.000627" ixy="0.0" iyz="0.0" ixz="0.0"/>
  </inertial>
  <visual>
    <origin xyz="0 0 0" rpy="0 0 0"/>
    <geometry>
      <mesh filename="package://basicBoomBot_description/meshes/base_link.stl" scale="0.001 0.001 0.001"/>
    </geometry>
    <material name="silver"/>
  </visual>
  <collision>
    <origin xyz="0 0 0" rpy="0 0 0"/>
    <geometry>
      <mesh filename="package://basicBoomBot_description/meshes/base_link.stl" scale="0.001 0.001 0.001"/>
    </geometry>
  </collision>
</link>

<link name="wheel_fl_1">
  <inertial>
    <origin xyz="0.0 0.007500000000000007 -6.938893903907228e-18" rpy="0 0 0"/>
    <mass value="0.03799363615435155"/>
    <inertia ixx="7e-06" iyy="1.2e-05" izz="7e-06" ixy="0.0" iyz="-0.0" ixz="0.0"/>
  </inertial>
  <visual>
    <origin xyz="-0.05 -0.053 -0.025" rpy="0 0 0"/>
    <geometry>
      <mesh filename="package://basicBoomBot_description/meshes/wheel_fl_1.stl" scale="0.001 0.001 0.001"/>
    </geometry>
    <material name="silver"/>
  </visual>
  <collision>
    <origin xyz="-0.05 -0.053 -0.025" rpy="0 0 0"/>
    <geometry>
      <mesh filename="package://basicBoomBot_description/meshes/wheel_fl_1.stl" scale="0.001 0.001 0.001"/>
    </geometry>
  </collision>
</link>

<link name="wheel_bl_1">
  <inertial>
    <origin xyz="0.0 0.007500000000000007 -6.938893903907228e-18" rpy="0 0 0"/>
    <mass value="0.03799363615435155"/>
    <inertia ixx="7e-06" iyy="1.2e-05" izz="7e-06" ixy="-0.0" iyz="-0.0" ixz="-0.0"/>
  </inertial>
  <visual>
    <origin xyz="0.05 -0.053 -0.025" rpy="0 0 0"/>
    <geometry>
      <mesh filename="package://basicBoomBot_description/meshes/wheel_bl_1.stl" scale="0.001 0.001 0.001"/>
    </geometry>
    <material name="silver"/>
  </visual>
  <collision>
    <origin xyz="0.05 -0.053 -0.025" rpy="0 0 0"/>
    <geometry>
      <mesh filename="package://basicBoomBot_description/meshes/wheel_bl_1.stl" scale="0.001 0.001 0.001"/>
    </geometry>
  </collision>
</link>

<link name="wheel_br_1">
  <inertial>
    <origin xyz="0.0 -0.0075 -6.938893903907228e-18" rpy="0 0 0"/>
    <mass value="0.03799363615435155"/>
    <inertia ixx="7e-06" iyy="1.2e-05" izz="7e-06" ixy="0.0" iyz="0.0" ixz="-0.0"/>
  </inertial>
  <visual>
    <origin xyz="0.05 0.053 -0.025" rpy="0 0 0"/>
    <geometry>
      <mesh filename="package://basicBoomBot_description/meshes/wheel_br_1.stl" scale="0.001 0.001 0.001"/>
    </geometry>
    <material name="silver"/>
  </visual>
  <collision>
    <origin xyz="0.05 0.053 -0.025" rpy="0 0 0"/>
    <geometry>
      <mesh filename="package://basicBoomBot_description/meshes/wheel_br_1.stl" scale="0.001 0.001 0.001"/>
    </geometry>
  </collision>
</link>

<link name="wheel_fr_1">
  <inertial>
    <origin xyz="0.0 -0.0075 -6.938893903907228e-18" rpy="0 0 0"/>
    <mass value="0.03799363615435155"/>
    <inertia ixx="7e-06" iyy="1.2e-05" izz="7e-06" ixy="-0.0" iyz="0.0" ixz="0.0"/>
  </inertial>
  <visual>
    <origin xyz="-0.05 0.053 -0.025" rpy="0 0 0"/>
    <geometry>
      <mesh filename="package://basicBoomBot_description/meshes/wheel_fr_1.stl" scale="0.001 0.001 0.001"/>
    </geometry>
    <material name="silver"/>
  </visual>
  <collision>
    <origin xyz="-0.05 0.053 -0.025" rpy="0 0 0"/>
    <geometry>
      <mesh filename="package://basicBoomBot_description/meshes/wheel_fr_1.stl" scale="0.001 0.001 0.001"/>
    </geometry>
  </collision>
</link>

<link name="lidar_1">
  <inertial>
    <origin xyz="-2.840646112429589e-18 0.0 0.004977758094415835" rpy="0 0 0"/>
    <mass value="0.016133655739795163"/>
    <inertia ixx="2e-06" iyy="2e-06" izz="3e-06" ixy="0.0" iyz="-0.0" ixz="-0.0"/>
  </inertial>
  <visual>
    <origin xyz="-0.0 -0.0 -0.095" rpy="0 0 0"/>
    <geometry>
      <mesh filename="package://basicBoomBot_description/meshes/lidar_1.stl" scale="0.001 0.001 0.001"/>
    </geometry>
    <material name="silver"/>
  </visual>
  <collision>
    <origin xyz="-0.0 -0.0 -0.095" rpy="0 0 0"/>
    <geometry>
      <mesh filename="package://basicBoomBot_description/meshes/lidar_1.stl" scale="0.001 0.001 0.001"/>
    </geometry>
  </collision>
</link>

<link name="camera_1">
  <inertial>
    <origin xyz="0.004971127746877635 -1.2511913814258638e-18 6.938893903907228e-18" rpy="0 0 0"/>
    <mass value="0.0022893183617270826"/>
    <inertia ixx="0.0" iyy="0.0" izz="0.0" ixy="-0.0" iyz="0.0" ixz="0.0"/>
  </inertial>
  <visual>
    <origin xyz="-0.0505 -0.0 -0.055" rpy="0 0 0"/>
    <geometry>
      <mesh filename="package://basicBoomBot_description/meshes/camera_1.stl" scale="0.001 0.001 0.001"/>
    </geometry>
    <material name="silver"/>
  </visual>
  <collision>
    <origin xyz="-0.0505 -0.0 -0.055" rpy="0 0 0"/>
    <geometry>
      <mesh filename="package://basicBoomBot_description/meshes/camera_1.stl" scale="0.001 0.001 0.001"/>
    </geometry>
  </collision>
</link>

<link name="ultrasonic_sensor_1">
  <inertial>
    <origin xyz="0.0014740953993110303 4.288151633186198e-18 -6.938893903907228e-18" rpy="0 0 0"/>
    <mass value="0.000692645854851481"/>
    <inertia ixx="0.0" iyy="0.0" izz="0.0" ixy="0.0" iyz="-0.0" ixz="0.0"/>
  </inertial>
  <visual>
    <origin xyz="-0.0575 -0.0 -0.0395" rpy="0 0 0"/>
    <geometry>
      <mesh filename="package://basicBoomBot_description/meshes/ultrasonic_sensor_1.stl" scale="0.001 0.001 0.001"/>
    </geometry>
    <material name="silver"/>
  </visual>
  <collision>
    <origin xyz="-0.0575 -0.0 -0.0395" rpy="0 0 0"/>
    <geometry>
      <mesh filename="package://basicBoomBot_description/meshes/ultrasonic_sensor_1.stl" scale="0.001 0.001 0.001"/>
    </geometry>
  </collision>
</link>

<joint name="wheel_fl_joint" type="continuous">
  <origin xyz="0.05 0.053 0.025" rpy="0 0 0"/>
  <parent link="base_link"/>
  <child link="wheel_fl_1"/>
  <axis xyz="0.0 1.0 0.0"/>
</joint>

<joint name="wheel_bl_joint" type="continuous">
  <origin xyz="-0.05 0.053 0.025" rpy="0 0 0"/>
  <parent link="base_link"/>
  <child link="wheel_bl_1"/>
  <axis xyz="0.0 1.0 0.0"/>
</joint>

<joint name="wheel_br_joint" type="continuous">
  <origin xyz="-0.05 -0.053 0.025" rpy="0 0 0"/>
  <parent link="base_link"/>
  <child link="wheel_br_1"/>
  <axis xyz="0.0 -1.0 0.0"/>
</joint>

<joint name="wheel_fr_joint" type="continuous">
  <origin xyz="0.05 -0.053 0.025" rpy="0 0 0"/>
  <parent link="base_link"/>
  <child link="wheel_fr_1"/>
  <axis xyz="0.0 -1.0 0.0"/>
</joint>

<joint name="lidar_joint" type="fixed">
  <origin xyz="0.0 0.0 0.095" rpy="0 0 0"/>
  <parent link="base_link"/>
  <child link="lidar_1"/>
</joint>

<joint name="camera_joint" type="fixed">
  <origin xyz="0.0505 0.0 0.055" rpy="0 0 0"/>
  <parent link="base_link"/>
  <child link="camera_1"/>
</joint>

<joint name="Rigid7" type="fixed">
  <origin xyz="0.0575 0.0 0.0395" rpy="0 0 0"/>
  <parent link="base_link"/>
  <child link="ultrasonic_sensor_1"/>
</joint>

</robot>
